Workbook

Sheet Команда
A1: Роль | B1: ФИО (эксперт)
A2: Участник 1 | B2: Галенин Артем Владимирович
A3: Участник 2 | B3: Ревин Антон Алексеевич
A4: Участник 3 | B4: Ример Андрей Алексеевич
A5: Участник 4 | B5: Журавлев Виталий Вадимович
A7: Тема: Цифровизация вуза

Sheet Оценки_Критерии
A1: Критерий | B1: Уч.1 P | C1: Уч.1 E | D1: Уч.1 O | E1: Уч.2 P | F1: Уч.2 E | G1: Уч.2 O | H1: Уч.3 P | I1: Уч.3 E | J1: Уч.3 O | K1: Уч.4 P | L1: Уч.4 E | M1: Уч.4 O
A2: K1. Полезность для вуза | B2: 7 | C2: 9 | D2: 10 | E2: 6 | F2: 8 | G2: 10 | H2: 7 | I2: 8 | J2: 10 | K2: 6 | L2: 9 | M2: 10
A3: K2. Простота реализации | B3: 4 | C3: 7 | D3: 8 | E3: 5 | F3: 6 | G3: 9 | H3: 5 | I3: 7 | J3: 9 | K3: 4 | L3: 6 | M3: 8
A4: K3. Низкий риск | B4: 5 | C4: 7 | D4: 9 | E4: 4 | F4: 6 | G4: 8 | H4: 5 | I4: 6 | J4: 8 | K4: 4 | L4: 7 | M4: 9
A5: K4. Потенциал развития | B5: 6 | C5: 8 | D5: 9 | E5: 6 | F5: 9 | G5: 10 | H5: 7 | I5: 9 | J5: 10 | K5: 6 | L5: 8 | M5: 9

Sheet Критерии_agg
A1: Критерий | B1: a = min(P) | C1: b = mean(E) | D1: c = max(O) | E1: Defuzz (a+4b+c)/6 | F1: Чёткий вес | G1: Нечёткий вес w_a | H1: w_b | I1: w_c
A2: K1. Полезность для вуза | B2: =MIN(Оценки_Критерии!B2,Оценки_Критерии!E2,Оценки_Критерии!H2,Оценки_Критерии!K2) -> 6 | C2: =AVERAGE(Оценки_Критерии!C2,Оценки_Критерии!F2,Оценки_Критерии!I2,Оценки_Критерии!L2) -> 8.5 | D2: =MAX(Оценки_Критерии!D2,Оценки_Критерии!G2,Оценки_Критерии!J2,Оценки_Критерии!M2) -> 10 | E2: =(B2+4*C2+D2)/6 -> 8.3333333 | F2: =E2/SUM($E$2:$E$5) -> 0.28089888 | G2: =B2/10 -> 0.6 | H2: =C2/10 -> 0.85 | I2: =D2/10 -> 1
A3: K2. Простота реализации | B3: =MIN(Оценки_Критерии!B3,Оценки_Критерии!E3,Оценки_Критерии!H3,Оценки_Критерии!K3) -> 4 | C3: =AVERAGE(Оценки_Критерии!C3,Оценки_Критерии!F3,Оценки_Критерии!I3,Оценки_Критерии!L3) -> 6.5 | D3: =MAX(Оценки_Критерии!D3,Оценки_Критерии!G3,Оценки_Критерии!J3,Оценки_Критерии!M3) -> 9 | E3: =(B3+4*C3+D3)/6 -> 6.5 | F3: =E3/SUM($E$2:$E$5) -> 0.21910112 | G3: =B3/10 -> 0.4 | H3: =C3/10 -> 0.65 | I3: =D3/10 -> 0.9
A4: K3. Низкий риск | B4: =MIN(Оценки_Критерии!B4,Оценки_Критерии!E4,Оценки_Критерии!H4,Оценки_Критерии!K4) -> 4 | C4: =AVERAGE(Оценки_Критерии!C4,Оценки_Критерии!F4,Оценки_Критерии!I4,Оценки_Критерии!L4) -> 6.5 | D4: =MAX(Оценки_Критерии!D4,Оценки_Критерии!G4,Оценки_Критерии!J4,Оценки_Критерии!M4) -> 9 | E4: =(B4+4*C4+D4)/6 -> 6.5 | F4: =E4/SUM($E$2:$E$5) -> 0.21910112 | G4: =B4/10 -> 0.4 | H4: =C4/10 -> 0.65 | I4: =D4/10 -> 0.9
A5: K4. Потенциал развития | B5: =MIN(Оценки_Критерии!B5,Оценки_Критерии!E5,Оценки_Критерии!H5,Оценки_Критерии!K5) -> 6 | C5: =AVERAGE(Оценки_Критерии!C5,Оценки_Критерии!F5,Оценки_Критерии!I5,Оценки_Критерии!L5) -> 8.5 | D5: =MAX(Оценки_Критерии!D5,Оценки_Критерии!G5,Оценки_Критерии!J5,Оценки_Критерии!M5) -> 10 | E5: =(B5+4*C5+D5)/6 -> 8.3333333 | F5: =E5/SUM($E$2:$E$5) -> 0.28089888 | G5: =B5/10 -> 0.6 | H5: =C5/10 -> 0.85 | I5: =D5/10 -> 1

Sheet Оценки_Альтернативы
A1: Участник 1 | B1: =Команда!B2 -> Галенин Артем Владимирович
A2: Альтернатива | B2: K1P | C2: K1E | D2: K1O | E2: K2P | F2: K2E | G2: K2O | H2: K3P | I2: K3E | J2: K3O | K2: K4P | L2: K4E | M2: K4O
A3: A. Электронный студенческий офис | B3: 7 | C3: 9 | D3: 10 | E3: 5 | F3: 7 | G3: 8 | H3: 5 | I3: 7 | J3: 9 | K3: 6 | L3: 8 | M3: 9
A4: B. Умное расписание + аудитории | B4: 6 | C4: 8 | D4: 9 | E4: 6 | F4: 8 | G4: 9 | H4: 6 | I4: 8 | J4: 10 | K4: 6 | L4: 8 | M4: 9
A5: C. Портал научных проектов магистрантов | B5: 6 | C5: 8 | D5: 9 | E5: 4 | F5: 6 | G5: 7 | H5: 4 | I5: 6 | J5: 7 | K5: 7 | L5: 9 | M5: 10
A6: D. Личный кабинет абитуриента | B6: 7 | C6: 9 | D6: 10 | E6: 7 | F6: 9 | G6: 10 | H6: 6 | I6: 8 | J6: 9 | K6: 4 | L6: 6 | M6: 7
A8: Участник 2 | B8: =Команда!B3 -> Ревин Антон Алексеевич
A9: Альтернатива | B9: K1P | C9: K1E | D9: K1O | E9: K2P | F9: K2E | G9: K2O | H9: K3P | I9: K3E | J9: K3O | K9: K4P | L9: K4E | M9: K4O
A10: A. Электронный студенческий офис | B10: 6 | C10: 8 | D10: 9 | E10: 5 | F10: 6 | G10: 8 | H10: 5 | I10: 6 | J10: 8 | K10: 6 | L10: 8 | M10: 9
A11: B. Умное расписание + аудитории | B11: 6 | C11: 7 | D11: 9 | E11: 6 | F11: 8 | G11: 9 | H11: 7 | I11: 9 | J11: 10 | K11: 5 | L11: 7 | M11: 8
A12: C. Портал научных проектов магистрантов | B12: 5 | C12: 7 | D12: 8 | E12: 4 | F12: 5 | G12: 7 | H12: 4 | I12: 5 | J12: 6 | K12: 7 | L12: 8 | M12: 9
A13: D. Личный кабинет абитуриента | B13: 7 | C13: 9 | D13: 10 | E13: 7 | F13: 8 | G13: 9 | H13: 6 | I13: 8 | J13: 9 | K13: 4 | L13: 5 | M13: 7
A15: Участник 3 | B15: =Команда!B4 -> Ример Андрей Алексеевич
A16: Альтернатива | B16: K1P | C16: K1E | D16: K1O | E16: K2P | F16: K2E | G16: K2O | H16: K3P | I16: K3E | J16: K3O | K16: K4P | L16: K4E | M16: K4O
A17: A. Электронный студенческий офис | B17: 7 | C17: 8 | D17: 10 | E17: 4 | F17: 6 | G17: 8 | H17: 5 | I17: 7 | J17: 8 | K17: 7 | L17: 8 | M17: 9
A18: B. Умное расписание + аудитории | B18: 5 | C18: 7 | D18: 9 | E18: 6 | F18: 8 | G18: 9 | H18: 6 | I18: 8 | J18: 9 | K18: 5 | L18: 7 | M18: 9
A19: C. Портал научных проектов магистрантов | B19: 6 | C19: 8 | D19: 9 | E19: 4 | F19: 6 | G19: 7 | H19: 3 | I19: 5 | J19: 7 | K19: 7 | L19: 9 | M19: 10
A20: D. Личный кабинет абитуриента | B20: 7 | C20: 9 | D20: 10 | E20: 6 | F20: 8 | G20: 9 | H20: 6 | I20: 7 | J20: 9 | K20: 3 | L20: 5 | M20: 6
A22: Участник 4 | B22: =Команда!B5 -> Журавлев Виталий Вадимович
A23: Альтернатива | B23: K1P | C23: K1E | D23: K1O | E23: K2P | F23: K2E | G23: K2O | H23: K3P | I23: K3E | J23: K3O | K23: K4P | L23: K4E | M23: K4O
A24: A. Электронный студенческий офис | B24: 6 | C24: 8 | D24: 9 | E24: 5 | F24: 7 | G24: 8 | H24: 4 | I24: 6 | J24: 8 | K24: 6 | L24: 8 | M24: 10
A25: B. Умное расписание + аудитории | B25: 6 | C25: 8 | D25: 9 | E25: 7 | F25: 8 | G25: 10 | H25: 6 | I25: 8 | J25: 10 | K25: 5 | L25: 7 | M25: 8
A26: C. Портал научных проектов магистрантов | B26: 5 | C26: 7 | D26: 9 | E26: 3 | F26: 5 | G26: 7 | H26: 4 | I26: 6 | J26: 7 | K26: 6 | L26: 8 | M26: 10
A27: D. Личный кабинет абитуриента | B27: 8 | C27: 9 | D27: 10 | E27: 7 | F27: 9 | G27: 10 | H27: 6 | I27: 8 | J27: 9 | K27: 4 | L27: 6 | M27: 7

Sheet TOPSIS
A1: Шаг 1. Агрегированная нечёткая матрица решений
A2: Альтернатива | B2: K1_a | C2: K1_b | D2: K1_c | E2: K2_a | F2: K2_b | G2: K2_c | H2: K3_a | I2: K3_b | J2: K3_c | K2: K4_a | L2: K4_b | M2: K4_c
A3: A. Электронный студенческий офис | B3: =MIN(Оценки_Альтернативы!B3,Оценки_Альтернативы!B10,Оценки_Альтернативы!B17,Оценки_Альтернативы!B24) -> 6 | C3: =AVERAGE(Оценки_Альтернативы!C3,Оценки_Альтернативы!C10,Оценки_Альтернативы!C17,Оценки_Альтернативы!C24) -> 8.25 | D3: =MAX(Оценки_Альтернативы!D3,Оценки_Альтернативы!D10,Оценки_Альтернативы!D17,Оценки_Альтернативы!D24) -> 10 | E3: =MIN(Оценки_Альтернативы!E3,Оценки_Альтернативы!E10,Оценки_Альтернативы!E17,Оценки_Альтернативы!E24) -> 4 | F3: =AVERAGE(Оценки_Альтернативы!F3,Оценки_Альтернативы!F10,Оценки_Альтернативы!F17,Оценки_Альтернативы!F24) -> 6.5 | G3: =MAX(Оценки_Альтернативы!G3,Оценки_Альтернативы!G10,Оценки_Альтернативы!G17,Оценки_Альтернативы!G24) -> 8 | H3: =MIN(Оценки_Альтернативы!H3,Оценки_Альтернативы!H10,Оценки_Альтернативы!H17,Оценки_Альтернативы!H24) -> 4 | I3: =AVERAGE(Оценки_Альтернативы!I3,Оценки_Альтернативы!I10,Оценки_Альтернативы!I17,Оценки_Альтернативы!I24) -> 6.5 | J3: =MAX(Оценки_Альтернативы!J3,Оценки_Альтернативы!J10,Оценки_Альтернативы!J17,Оценки_Альтернативы!J24) -> 9 | K3: =MIN(Оценки_Альтернативы!K3,Оценки_Альтернативы!K10,Оценки_Альтернативы!K17,Оценки_Альтернативы!K24) -> 6 | L3: =AVERAGE(Оценки_Альтернативы!L3,Оценки_Альтернативы!L10,Оценки_Альтернативы!L17,Оценки_Альтернативы!L24) -> 8 | M3: =MAX(Оценки_Альтернативы!M3,Оценки_Альтернативы!M10,Оценки_Альтернативы!M17,Оценки_Альтернативы!M24) -> 10
A4: B. Умное расписание + аудитории | B4: =MIN(Оценки_Альтернативы!B4,Оценки_Альтернативы!B11,Оценки_Альтернативы!B18,Оценки_Альтернативы!B25) -> 5 | C4: =AVERAGE(Оценки_Альтернативы!C4,Оценки_Альтернативы!C11,Оценки_Альтернативы!C18,Оценки_Альтернативы!C25) -> 7.5 | D4: =MAX(Оценки_Альтернативы!D4,Оценки_Альтернативы!D11,Оценки_Альтернативы!D18,Оценки_Альтернативы!D25) -> 9 | E4: =MIN(Оценки_Альтернативы!E4,Оценки_Альтернативы!E11,Оценки_Альтернативы!E18,Оценки_Альтернативы!E25) -> 6 | F4: =AVERAGE(Оценки_Альтернативы!F4,Оценки_Альтернативы!F11,Оценки_Альтернативы!F18,Оценки_Альтернативы!F25) -> 8 | G4: =MAX(Оценки_Альтернативы!G4,Оценки_Альтернативы!G11,Оценки_Альтернативы!G18,Оценки_Альтернативы!G25) -> 10 | H4: =MIN(Оценки_Альтернативы!H4,Оценки_Альтернативы!H11,Оценки_Альтернативы!H18,Оценки_Альтернативы!H25) -> 6 | I4: =AVERAGE(Оценки_Альтернативы!I4,Оценки_Альтернативы!I11,Оценки_Альтернативы!I18,Оценки_Альтернативы!I25) -> 8.25 | J4: =MAX(Оценки_Альтернативы!J4,Оценки_Альтернативы!J11,Оценки_Альтернативы!J18,Оценки_Альтернативы!J25) -> 10 | K4: =MIN(Оценки_Альтернативы!K4,Оценки_Альтернативы!K11,Оценки_Альтернативы!K18,Оценки_Альтернативы!K25) -> 5 | L4: =AVERAGE(Оценки_Альтернативы!L4,Оценки_Альтернативы!L11,Оценки_Альтернативы!L18,Оценки_Альтернативы!L25) -> 7.25 | M4: =MAX(Оценки_Альтернативы!M4,Оценки_Альтернативы!M11,Оценки_Альтернативы!M18,Оценки_Альтернативы!M25) -> 9
A5: C. Портал научных проектов магистрантов | B5: =MIN(Оценки_Альтернативы!B5,Оценки_Альтернативы!B12,Оценки_Альтернативы!B19,Оценки_Альтернативы!B26) -> 5 | C5: =AVERAGE(Оценки_Альтернативы!C5,Оценки_Альтернативы!C12,Оценки_Альтернативы!C19,Оценки_Альтернативы!C26) -> 7.5 | D5: =MAX(Оценки_Альтернативы!D5,Оценки_Альтернативы!D12,Оценки_Альтернативы!D19,Оценки_Альтернативы!D26) -> 9 | E5: =MIN(Оценки_Альтернативы!E5,Оценки_Альтернативы!E12,Оценки_Альтернативы!E19,Оценки_Альтернативы!E26) -> 3 | F5: =AVERAGE(Оценки_Альтернативы!F5,Оценки_Альтернативы!F12,Оценки_Альтернативы!F19,Оценки_Альтернативы!F26) -> 5.5 | G5: =MAX(Оценки_Альтернативы!G5,Оценки_Альтернативы!G12,Оценки_Альтернативы!G19,Оценки_Альтернативы!G26) -> 7 | H5: =MIN(Оценки_Альтернативы!H5,Оценки_Альтернативы!H12,Оценки_Альтернативы!H19,Оценки_Альтернативы!H26) -> 3 | I5: =AVERAGE(Оценки_Альтернативы!I5,Оценки_Альтернативы!I12,Оценки_Альтернативы!I19,Оценки_Альтернативы!I26) -> 5.5 | J5: =MAX(Оценки_Альтернативы!J5,Оценки_Альтернативы!J12,Оценки_Альтернативы!J19,Оценки_Альтернативы!J26) -> 7 | K5: =MIN(Оценки_Альтернативы!K5,Оценки_Альтернативы!K12,Оценки_Альтернативы!K19,Оценки_Альтернативы!K26) -> 6 | L5: =AVERAGE(Оценки_Альтернативы!L5,Оценки_Альтернативы!L12,Оценки_Альтернативы!L19,Оценки_Альтернативы!L26) -> 8.5 | M5: =MAX(Оценки_Альтернативы!M5,Оценки_Альтернативы!M12,Оценки_Альтернативы!M19,Оценки_Альтернативы!M26) -> 10
A6: D. Личный кабинет абитуриента | B6: =MIN(Оценки_Альтернативы!B6,Оценки_Альтернативы!B13,Оценки_Альтернативы!B20,Оценки_Альтернативы!B27) -> 7 | C6: =AVERAGE(Оценки_Альтернативы!C6,Оценки_Альтернативы!C13,Оценки_Альтернативы!C20,Оценки_Альтернативы!C27) -> 9 | D6: =MAX(Оценки_Альтернативы!D6,Оценки_Альтернативы!D13,Оценки_Альтернативы!D20,Оценки_Альтернативы!D27) -> 10 | E6: =MIN(Оценки_Альтернативы!E6,Оценки_Альтернативы!E13,Оценки_Альтернативы!E20,Оценки_Альтернативы!E27) -> 6 | F6: =AVERAGE(Оценки_Альтернативы!F6,Оценки_Альтернативы!F13,Оценки_Альтернативы!F20,Оценки_Альтернативы!F27) -> 8.5 | G6: =MAX(Оценки_Альтернативы!G6,Оценки_Альтернативы!G13,Оценки_Альтернативы!G20,Оценки_Альтернативы!G27) -> 10 | H6: =MIN(Оценки_Альтернативы!H6,Оценки_Альтернативы!H13,Оценки_Альтернативы!H20,Оценки_Альтернативы!H27) -> 6 | I6: =AVERAGE(Оценки_Альтернативы!I6,Оценки_Альтернативы!I13,Оценки_Альтернативы!I20,Оценки_Альтернативы!I27) -> 7.75 | J6: =MAX(Оценки_Альтернативы!J6,Оценки_Альтернативы!J13,Оценки_Альтернативы!J20,Оценки_Альтернативы!J27) -> 9 | K6: =MIN(Оценки_Альтернативы!K6,Оценки_Альтернативы!K13,Оценки_Альтернативы!K20,Оценки_Альтернативы!K27) -> 3 | L6: =AVERAGE(Оценки_Альтернативы!L6,Оценки_Альтернативы!L13,Оценки_Альтернативы!L20,Оценки_Альтернативы!L27) -> 5.5 | M6: =MAX(Оценки_Альтернативы!M6,Оценки_Альтернативы!M13,Оценки_Альтернативы!M20,Оценки_Альтернативы!M27) -> 7
A8: Шаг 2. Нормализация (все критерии — «чем больше, тем лучше»: деление на c*_j = max c_ij по критерию)
A9: Альтернатива | B9: K1_a_n | C9: K1_b_n | D9: K1_c_n | E9: K2_a_n | F9: K2_b_n | G9: K2_c_n | H9: K3_a_n | I9: K3_b_n | J9: K3_c_n | K9: K4_a_n | L9: K4_b_n | M9: K4_c_n
A10: A. Электронный студенческий офис | B10: =B3/MAX($D$3:$D$6) -> 0.6 | C10: =C3/MAX($D$3:$D$6) -> 0.825 | D10: =D3/MAX($D$3:$D$6) -> 1 | E10: =E3/MAX($G$3:$G$6) -> 0.4 | F10: =F3/MAX($G$3:$G$6) -> 0.65 | G10: =G3/MAX($G$3:$G$6) -> 0.8 | H10: =H3/MAX($J$3:$J$6) -> 0.4 | I10: =I3/MAX($J$3:$J$6) -> 0.65 | J10: =J3/MAX($J$3:$J$6) -> 0.9 | K10: =K3/MAX($M$3:$M$6) -> 0.6 | L10: =L3/MAX($M$3:$M$6) -> 0.8 | M10: =M3/MAX($M$3:$M$6) -> 1
A11: B. Умное расписание + аудитории | B11: =B4/MAX($D$3:$D$6) -> 0.5 | C11: =C4/MAX($D$3:$D$6) -> 0.75 | D11: =D4/MAX($D$3:$D$6) -> 0.9 | E11: =E4/MAX($G$3:$G$6) -> 0.6 | F11: =F4/MAX($G$3:$G$6) -> 0.8 | G11: =G4/MAX($G$3:$G$6) -> 1 | H11: =H4/MAX($J$3:$J$6) -> 0.6 | I11: =I4/MAX($J$3:$J$6) -> 0.825 | J11: =J4/MAX($J$3:$J$6) -> 1 | K11: =K4/MAX($M$3:$M$6) -> 0.5 | L11: =L4/MAX($M$3:$M$6) -> 0.725 | M11: =M4/MAX($M$3:$M$6) -> 0.9
A12: C. Портал научных проектов магистрантов | B12: =B5/MAX($D$3:$D$6) -> 0.5 | C12: =C5/MAX($D$3:$D$6) -> 0.75 | D12: =D5/MAX($D$3:$D$6) -> 0.9 | E12: =E5/MAX($G$3:$G$6) -> 0.3 | F12: =F5/MAX($G$3:$G$6) -> 0.55 | G12: =G5/MAX($G$3:$G$6) -> 0.7 | H12: =H5/MAX($J$3:$J$6) -> 0.3 | I12: =I5/MAX($J$3:$J$6) -> 0.55 | J12: =J5/MAX($J$3:$J$6) -> 0.7 | K12: =K5/MAX($M$3:$M$6) -> 0.6 | L12: =L5/MAX($M$3:$M$6) -> 0.85 | M12: =M5/MAX($M$3:$M$6) -> 1
A13: D. Личный кабинет абитуриента | B13: =B6/MAX($D$3:$D$6) -> 0.7 | C13: =C6/MAX($D$3:$D$6) -> 0.9 | D13: =D6/MAX($D$3:$D$6) -> 1 | E13: =E6/MAX($G$3:$G$6) -> 0.6 | F13: =F6/MAX($G$3:$G$6) -> 0.85 | G13: =G6/MAX($G$3:$G$6) -> 1 | H13: =H6/MAX($J$3:$J$6) -> 0.6 | I13: =I6/MAX($J$3:$J$6) -> 0.775 | J13: =J6/MAX($J$3:$J$6) -> 0.9 | K13: =K6/MAX($M$3:$M$6) -> 0.3 | L13: =L6/MAX($M$3:$M$6) -> 0.55 | M13: =M6/MAX($M$3:$M$6) -> 0.7
A15: Шаг 3. Взвешенная нормализованная матрица (умножение треугольных чисел: a·w_a, b·w_b, c·w_c)
A16: Альтернатива | B16: K1_a_v | C16: K1_b_v | D16: K1_c_v | E16: K2_a_v | F16: K2_b_v | G16: K2_c_v | H16: K3_a_v | I16: K3_b_v | J16: K3_c_v | K16: K4_a_v | L16: K4_b_v | M16: K4_c_v
A17: A. Электронный студенческий офис | B17: =B10*Критерии_agg!$G$2 -> 0.36 | C17: =C10*Критерии_agg!$H$2 -> 0.70125 | D17: =D10*Критерии_agg!$I$2 -> 1 | E17: =E10*Критерии_agg!$G$3 -> 0.16 | F17: =F10*Критерии_agg!$H$3 -> 0.4225 | G17: =G10*Критерии_agg!$I$3 -> 0.72 | H17: =H10*Критерии_agg!$G$4 -> 0.16 | I17: =I10*Критерии_agg!$H$4 -> 0.4225 | J17: =J10*Критерии_agg!$I$4 -> 0.81 | K17: =K10*Критерии_agg!$G$5 -> 0.36 | L17: =L10*Критерии_agg!$H$5 -> 0.68 | M17: =M10*Критерии_agg!$I$5 -> 1
A18: B. Умное расписание + аудитории | B18: =B11*Критерии_agg!$G$2 -> 0.3 | C18: =C11*Критерии_agg!$H$2 -> 0.6375 | D18: =D11*Критерии_agg!$I$2 -> 0.9 | E18: =E11*Критерии_agg!$G$3 -> 0.24 | F18: =F11*Критерии_agg!$H$3 -> 0.52 | G18: =G11*Критерии_agg!$I$3 -> 0.9 | H18: =H11*Критерии_agg!$G$4 -> 0.24 | I18: =I11*Критерии_agg!$H$4 -> 0.53625 | J18: =J11*Критерии_agg!$I$4 -> 0.9 | K18: =K11*Критерии_agg!$G$5 -> 0.3 | L18: =L11*Критерии_agg!$H$5 -> 0.61625 | M18: =M11*Критерии_agg!$I$5 -> 0.9
A19: C. Портал научных проектов магистрантов | B19: =B12*Критерии_agg!$G$2 -> 0.3 | C19: =C12*Критерии_agg!$H$2 -> 0.6375 | D19: =D12*Критерии_agg!$I$2 -> 0.9 | E19: =E12*Критерии_agg!$G$3 -> 0.12 | F19: =F12*Критерии_agg!$H$3 -> 0.3575 | G19: =G12*Критерии_agg!$I$3 -> 0.63 | H19: =H12*Критерии_agg!$G$4 -> 0.12 | I19: =I12*Критерии_agg!$H$4 -> 0.3575 | J19: =J12*Критерии_agg!$I$4 -> 0.63 | K19: =K12*Критерии_agg!$G$5 -> 0.36 | L19: =L12*Критерии_agg!$H$5 -> 0.7225 | M19: =M12*Критерии_agg!$I$5 -> 1
A20: D. Личный кабинет абитуриента | B20: =B13*Критерии_agg!$G$2 -> 0.42 | C20: =C13*Критерии_agg!$H$2 -> 0.765 | D20: =D13*Критерии_agg!$I$2 -> 1 | E20: =E13*Критерии_agg!$G$3 -> 0.24 | F20: =F13*Критерии_agg!$H$3 -> 0.5525 | G20: =G13*Критерии_agg!$I$3 -> 0.9 | H20: =H13*Критерии_agg!$G$4 -> 0.24 | I20: =I13*Критерии_agg!$H$4 -> 0.50375 | J20: =J13*Критерии_agg!$I$4 -> 0.81 | K20: =K13*Критерии_agg!$G$5 -> 0.18 | L20: =L13*Критерии_agg!$H$5 -> 0.4675 | M20: =M13*Критерии_agg!$I$5 -> 0.7
A22: Шаг 4. Нечёткое идеальное и анти-идеальное решения по Чену для нормированной матрицы
A23: Нормир. a⁻_j (min a по критерию) | B23: =MIN(B10:B13) -> 0.5 | E23: =MIN(E10:E13) -> 0.3 | H23: =MIN(H10:H13) -> 0.3 | K23: =MIN(K10:K13) -> 0.3
A25: V⁺ (FPIS) | B25: =1*Критерии_agg!$G$2 -> 0.6 | C25: =1*Критерии_agg!$H$2 -> 0.85 | D25: =1*Критерии_agg!$I$2 -> 1 | E25: =1*Критерии_agg!$G$3 -> 0.4 | F25: =1*Критерии_agg!$H$3 -> 0.65 | G25: =1*Критерии_agg!$I$3 -> 0.9 | H25: =1*Критерии_agg!$G$4 -> 0.4 | I25: =1*Критерии_agg!$H$4 -> 0.65 | J25: =1*Критерии_agg!$I$4 -> 0.9 | K25: =1*Критерии_agg!$G$5 -> 0.6 | L25: =1*Критерии_agg!$H$5 -> 0.85 | M25: =1*Критерии_agg!$I$5 -> 1
A26: V⁻ (FNIS) | B26: =$B$23*Критерии_agg!$G$2 -> 0.3 | C26: =$B$23*Критерии_agg!$H$2 -> 0.425 | D26: =$B$23*Критерии_agg!$I$2 -> 0.5 | E26: =$E$23*Критерии_agg!$G$3 -> 0.12 | F26: =$E$23*Критерии_agg!$H$3 -> 0.195 | G26: =$E$23*Критерии_agg!$I$3 -> 0.27 | H26: =$H$23*Критерии_agg!$G$4 -> 0.12 | I26: =$H$23*Критерии_agg!$H$4 -> 0.195 | J26: =$H$23*Критерии_agg!$I$4 -> 0.27 | K26: =$K$23*Критерии_agg!$G$5 -> 0.18 | L26: =$K$23*Критерии_agg!$H$5 -> 0.255 | M26: =$K$23*Критерии_agg!$I$5 -> 0.3
A28: Шаг 5. Расстояния (вершинный метод)
A29: Альтернатива | B29: d⁺ K1 | C29: d⁺ K2 | D29: d⁺ K3 | E29: d⁺ K4 | F29: d⁺ | G29: d⁻ K1 | H29: d⁻ K2 | I29: d⁻ K3 | J29: d⁻ K4 | K29: d⁻ | L29: CC = d⁻/(d⁺+d⁻) | M29: Ранг
A30: A. Электронный студенческий офис | B30: =SQRT(((B17-B$25)^2+(C17-C$25)^2+(D17-D$25)^2)/3) -> 0.16302 | C30: =SQRT(((E17-E$25)^2+(F17-F$25)^2+(G17-G$25)^2)/3) -> 0.21737544 | D30: =SQRT(((H17-H$25)^2+(I17-I$25)^2+(J17-J$25)^2)/3) -> 0.19786885 | E30: =SQRT(((K17-K$25)^2+(L17-L$25)^2+(M17-M$25)^2)/3) -> 0.16980381 | F30: =SUM(B30:E30) -> 0.74806811 | G30: =SQRT(((B17-B$26)^2+(C17-C$26)^2+(D17-D$26)^2)/3) -> 0.33161929 | H30: =SQRT(((E17-E$26)^2+(F17-F$26)^2+(G17-G$26)^2)/3) -> 0.29203667 | I30: =SQRT(((H17-H$26)^2+(I17-I$26)^2+(J17-J$26)^2)/3) -> 0.339095 | J30: =SQRT(((K17-K$26)^2+(L17-L$26)^2+(M17-M$26)^2)/3) -> 0.48408849 | K30: =SUM(G30:J30) -> 1.4468394 | L30: =K30/(F30+K30) -> 0.65918013 | M30: =RANK(L30,$L$30:$L$33) -> 2
A31: B. Умное расписание + аудитории | B31: =SQRT(((B18-B$25)^2+(C18-C$25)^2+(D18-D$25)^2)/3) -> 0.21996685 | C31: =SQRT(((E18-E$25)^2+(F18-F$25)^2+(G18-G$25)^2)/3) -> 0.11902381 | D31: =SQRT(((H18-H$25)^2+(I18-I$25)^2+(J18-J$25)^2)/3) -> 0.11334176 | E31: =SQRT(((K18-K$25)^2+(L18-L$25)^2+(M18-M$25)^2)/3) -> 0.22703822 | F31: =SUM(B31:E31) -> 0.67937064 | G31: =SQRT(((B18-B$26)^2+(C18-C$26)^2+(D18-D$26)^2)/3) -> 0.26150605 | H31: =SQRT(((E18-E$26)^2+(F18-F$26)^2+(G18-G$26)^2)/3) -> 0.41510039 | I31: =SQRT(((H18-H$26)^2+(I18-I$26)^2+(J18-J$26)^2)/3) -> 0.41942483 | J31: =SQRT(((K18-K$26)^2+(L18-L$26)^2+(M18-M$26)^2)/3) -> 0.41024446 | K31: =SUM(G31:J31) -> 1.5062757 | L31: =K31/(F31+K31) -> 0.68916717 | M31: =RANK(L31,$L$30:$L$33) -> 1
A32: C. Портал научных проектов магистрантов | B32: =SQRT(((B19-B$25)^2+(C19-C$25)^2+(D19-D$25)^2)/3) -> 0.21996685 | C32: =SQRT(((E19-E$25)^2+(F19-F$25)^2+(G19-G$25)^2)/3) -> 0.28098413 | D32: =SQRT(((H19-H$25)^2+(I19-I$25)^2+(J19-J$25)^2)/3) -> 0.28098413 | E32: =SQRT(((K19-K$25)^2+(L19-L$25)^2+(M19-M$25)^2)/3) -> 0.15690363 | F32: =SUM(B32:E32) -> 0.93883875 | G32: =SQRT(((B19-B$26)^2+(C19-C$26)^2+(D19-D$26)^2)/3) -> 0.26150605 | H32: =SQRT(((E19-E$26)^2+(F19-F$26)^2+(G19-G$26)^2)/3) -> 0.22803965 | I32: =SQRT(((H19-H$26)^2+(I19-I$26)^2+(J19-J$26)^2)/3) -> 0.22803965 | J32: =SQRT(((K19-K$26)^2+(L19-L$26)^2+(M19-M$26)^2)/3) -> 0.49697627 | K32: =SUM(G32:J32) -> 1.2145616 | L32: =K32/(F32+K32) -> 0.56402035 | M32: =RANK(L32,$L$30:$L$33) -> 4
A33: D. Личный кабинет абитуриента | B33: =SQRT(((B20-B$25)^2+(C20-C$25)^2+(D20-D$25)^2)/3) -> 0.11492751 | C33: =SQRT(((E20-E$25)^2+(F20-F$25)^2+(G20-G$25)^2)/3) -> 0.10817617 | D33: =SQRT(((H20-H$25)^2+(I20-I$25)^2+(J20-J$25)^2)/3) -> 0.13551022 | E33: =SQRT(((K20-K$25)^2+(L20-L$25)^2+(M20-M$25)^2)/3) -> 0.37090262 | F33: =SUM(B33:E33) -> 0.72951652 | G33: =SQRT(((B20-B$26)^2+(C20-C$26)^2+(D20-D$26)^2)/3) -> 0.35590261 | H33: =SQRT(((E20-E$26)^2+(F20-F$26)^2+(G20-G$26)^2)/3) -> 0.42391283 | I33: =SQRT(((H20-H$26)^2+(I20-I$26)^2+(J20-J$26)^2)/3) -> 0.36575336 | J33: =SQRT(((K20-K$26)^2+(L20-L$26)^2+(M20-M$26)^2)/3) -> 0.26150605 | K33: =SUM(G33:J33) -> 1.4070748 | L33: =K33/(F33+K33) -> 0.65856058 | M33: =RANK(L33,$L$30:$L$33) -> 3

Sheet МАИ
A1: 1. Критерии: попарное сравнение важности
A2: Эксперт 1 | B2: K1 | C2: K2 | D2: K3 | E2: K4
A3: K1. Полезность для вуза | B3: =IF(Оценки_Критерии!$C$2>=Оценки_Критерии!$C$2,MIN(9,1+Оценки_Критерии!$C$2-Оценки_Критерии!$C$2),1/MIN(9,1+Оценки_Критерии!$C$2-Оценки_Критерии!$C$2)) -> 1 | C3: =IF(Оценки_Критерии!$C$2>=Оценки_Критерии!$C$3,MIN(9,1+Оценки_Критерии!$C$2-Оценки_Критерии!$C$3),1/MIN(9,1+Оценки_Критерии!$C$3-Оценки_Критерии!$C$2)) -> 3 | D3: =IF(Оценки_Критерии!$C$2>=Оценки_Критерии!$C$4,MIN(9,1+Оценки_Критерии!$C$2-Оценки_Критерии!$C$4),1/MIN(9,1+Оценки_Критерии!$C$4-Оценки_Критерии!$C$2)) -> 3 | E3: =IF(Оценки_Критерии!$C$2>=Оценки_Критерии!$C$5,MIN(9,1+Оценки_Критерии!$C$2-Оценки_Критерии!$C$5),1/MIN(9,1+Оценки_Критерии!$C$5-Оценки_Критерии!$C$2)) -> 2
A4: K2. Простота реализации | B4: =IF(Оценки_Критерии!$C$3>=Оценки_Критерии!$C$2,MIN(9,1+Оценки_Критерии!$C$3-Оценки_Критерии!$C$2),1/MIN(9,1+Оценки_Критерии!$C$2-Оценки_Критерии!$C$3)) -> 0.33333333 | C4: =IF(Оценки_Критерии!$C$3>=Оценки_Критерии!$C$3,MIN(9,1+Оценки_Критерии!$C$3-Оценки_Критерии!$C$3),1/MIN(9,1+Оценки_Критерии!$C$3-Оценки_Критерии!$C$3)) -> 1 | D4: =IF(Оценки_Критерии!$C$3>=Оценки_Критерии!$C$4,MIN(9,1+Оценки_Критерии!$C$3-Оценки_Критерии!$C$4),1/MIN(9,1+Оценки_Критерии!$C$4-Оценки_Критерии!$C$3)) -> 1 | E4: =IF(Оценки_Критерии!$C$3>=Оценки_Критерии!$C$5,MIN(9,1+Оценки_Критерии!$C$3-Оценки_Критерии!$C$5),1/MIN(9,1+Оценки_Критерии!$C$5-Оценки_Критерии!$C$3)) -> 0.5
A5: K3. Низкий риск | B5: =IF(Оценки_Критерии!$C$4>=Оценки_Критерии!$C$2,MIN(9,1+Оценки_Критерии!$C$4-Оценки_Критерии!$C$2),1/MIN(9,1+Оценки_Критерии!$C$2-Оценки_Критерии!$C$4)) -> 0.33333333 | C5: =IF(Оценки_Критерии!$C$4>=Оценки_Критерии!$C$3,MIN(9,1+Оценки_Критерии!$C$4-Оценки_Критерии!$C$3),1/MIN(9,1+Оценки_Критерии!$C$3-Оценки_Критерии!$C$4)) -> 1 | D5: =IF(Оценки_Критерии!$C$4>=Оценки_Критерии!$C$4,MIN(9,1+Оценки_Критерии!$C$4-Оценки_Критерии!$C$4),1/MIN(9,1+Оценки_Критерии!$C$4-Оценки_Критерии!$C$4)) -> 1 | E5: =IF(Оценки_Критерии!$C$4>=Оценки_Критерии!$C$5,MIN(9,1+Оценки_Критерии!$C$4-Оценки_Критерии!$C$5),1/MIN(9,1+Оценки_Критерии!$C$5-Оценки_Критерии!$C$4)) -> 0.5
A6: K4. Потенциал развития | B6: =IF(Оценки_Критерии!$C$5>=Оценки_Критерии!$C$2,MIN(9,1+Оценки_Критерии!$C$5-Оценки_Критерии!$C$2),1/MIN(9,1+Оценки_Критерии!$C$2-Оценки_Критерии!$C$5)) -> 0.5 | C6: =IF(Оценки_Критерии!$C$5>=Оценки_Критерии!$C$3,MIN(9,1+Оценки_Критерии!$C$5-Оценки_Критерии!$C$3),1/MIN(9,1+Оценки_Критерии!$C$3-Оценки_Критерии!$C$5)) -> 2 | D6: =IF(Оценки_Критерии!$C$5>=Оценки_Критерии!$C$4,MIN(9,1+Оценки_Критерии!$C$5-Оценки_Критерии!$C$4),1/MIN(9,1+Оценки_Критерии!$C$4-Оценки_Критерии!$C$5)) -> 2 | E6: =IF(Оценки_Критерии!$C$5>=Оценки_Критерии!$C$5,MIN(9,1+Оценки_Критерии!$C$5-Оценки_Критерии!$C$5),1/MIN(9,1+Оценки_Критерии!$C$5-Оценки_Критерии!$C$5)) -> 1
A8: Эксперт 2 | B8: K1 | C8: K2 | D8: K3 | E8: K4
A9: K1. Полезность для вуза | B9: =IF(Оценки_Критерии!$F$2>=Оценки_Критерии!$F$2,MIN(9,1+Оценки_Критерии!$F$2-Оценки_Критерии!$F$2),1/MIN(9,1+Оценки_Критерии!$F$2-Оценки_Критерии!$F$2)) -> 1 | C9: =IF(Оценки_Критерии!$F$2>=Оценки_Критерии!$F$3,MIN(9,1+Оценки_Критерии!$F$2-Оценки_Критерии!$F$3),1/MIN(9,1+Оценки_Критерии!$F$3-Оценки_Критерии!$F$2)) -> 3 | D9: =IF(Оценки_Критерии!$F$2>=Оценки_Критерии!$F$4,MIN(9,1+Оценки_Критерии!$F$2-Оценки_Критерии!$F$4),1/MIN(9,1+Оценки_Критерии!$F$4-Оценки_Критерии!$F$2)) -> 3 | E9: =IF(Оценки_Критерии!$F$2>=Оценки_Критерии!$F$5,MIN(9,1+Оценки_Критерии!$F$2-Оценки_Критерии!$F$5),1/MIN(9,1+Оценки_Критерии!$F$5-Оценки_Критерии!$F$2)) -> 0.5
A10: K2. Простота реализации | B10: =IF(Оценки_Критерии!$F$3>=Оценки_Критерии!$F$2,MIN(9,1+Оценки_Критерии!$F$3-Оценки_Критерии!$F$2),1/MIN(9,1+Оценки_Критерии!$F$2-Оценки_Критерии!$F$3)) -> 0.33333333 | C10: =IF(Оценки_Критерии!$F$3>=Оценки_Критерии!$F$3,MIN(9,1+Оценки_Критерии!$F$3-Оценки_Критерии!$F$3),1/MIN(9,1+Оценки_Критерии!$F$3-Оценки_Критерии!$F$3)) -> 1 | D10: =IF(Оценки_Критерии!$F$3>=Оценки_Критерии!$F$4,MIN(9,1+Оценки_Критерии!$F$3-Оценки_Критерии!$F$4),1/MIN(9,1+Оценки_Критерии!$F$4-Оценки_Критерии!$F$3)) -> 1 | E10: =IF(Оценки_Критерии!$F$3>=Оценки_Критерии!$F$5,MIN(9,1+Оценки_Критерии!$F$3-Оценки_Критерии!$F$5),1/MIN(9,1+Оценки_Критерии!$F$5-Оценки_Критерии!$F$3)) -> 0.25
A11: K3. Низкий риск | B11: =IF(Оценки_Критерии!$F$4>=Оценки_Критерии!$F$2,MIN(9,1+Оценки_Критерии!$F$4-Оценки_Критерии!$F$2),1/MIN(9,1+Оценки_Критерии!$F$2-Оценки_Критерии!$F$4)) -> 0.33333333 | C11: =IF(Оценки_Критерии!$F$4>=Оценки_Критерии!$F$3,MIN(9,1+Оценки_Критерии!$F$4-Оценки_Критерии!$F$3),1/MIN(9,1+Оценки_Критерии!$F$3-Оценки_Критерии!$F$4)) -> 1 | D11: =IF(Оценки_Критерии!$F$4>=Оценки_Критерии!$F$4,MIN(9,1+Оценки_Критерии!$F$4-Оценки_Критерии!$F$4),1/MIN(9,1+Оценки_Критерии!$F$4-Оценки_Критерии!$F$4)) -> 1 | E11: =IF(Оценки_Критерии!$F$4>=Оценки_Критерии!$F$5,MIN(9,1+Оценки_Критерии!$F$4-Оценки_Критерии!$F$5),1/MIN(9,1+Оценки_Критерии!$F$5-Оценки_Критерии!$F$4)) -> 0.25
A12: K4. Потенциал развития | B12: =IF(Оценки_Критерии!$F$5>=Оценки_Критерии!$F$2,MIN(9,1+Оценки_Критерии!$F$5-Оценки_Критерии!$F$2),1/MIN(9,1+Оценки_Критерии!$F$2-Оценки_Критерии!$F$5)) -> 2 | C12: =IF(Оценки_Критерии!$F$5>=Оценки_Критерии!$F$3,MIN(9,1+Оценки_Критерии!$F$5-Оценки_Критерии!$F$3),1/MIN(9,1+Оценки_Критерии!$F$3-Оценки_Критерии!$F$5)) -> 4 | D12: =IF(Оценки_Критерии!$F$5>=Оценки_Критерии!$F$4,MIN(9,1+Оценки_Критерии!$F$5-Оценки_Критерии!$F$4),1/MIN(9,1+Оценки_Критерии!$F$4-Оценки_Критерии!$F$5)) -> 4 | E12: =IF(Оценки_Критерии!$F$5>=Оценки_Критерии!$F$5,MIN(9,1+Оценки_Критерии!$F$5-Оценки_Критерии!$F$5),1/MIN(9,1+Оценки_Критерии!$F$5-Оценки_Критерии!$F$5)) -> 1
A14: Эксперт 3 | B14: K1 | C14: K2 | D14: K3 | E14: K4
A15: K1. Полезность для вуза | B15: =IF(Оценки_Критерии!$I$2>=Оценки_Критерии!$I$2,MIN(9,1+Оценки_Критерии!$I$2-Оценки_Критерии!$I$2),1/MIN(9,1+Оценки_Критерии!$I$2-Оценки_Критерии!$I$2)) -> 1 | C15: =IF(Оценки_Критерии!$I$2>=Оценки_Критерии!$I$3,MIN(9,1+Оценки_Критерии!$I$2-Оценки_Критерии!$I$3),1/MIN(9,1+Оценки_Критерии!$I$3-Оценки_Критерии!$I$2)) -> 2 | D15: =IF(Оценки_Критерии!$I$2>=Оценки_Критерии!$I$4,MIN(9,1+Оценки_Критерии!$I$2-Оценки_Критерии!$I$4),1/MIN(9,1+Оценки_Критерии!$I$4-Оценки_Критерии!$I$2)) -> 3 | E15: =IF(Оценки_Критерии!$I$2>=Оценки_Критерии!$I$5,MIN(9,1+Оценки_Критерии!$I$2-Оценки_Критерии!$I$5),1/MIN(9,1+Оценки_Критерии!$I$5-Оценки_Критерии!$I$2)) -> 0.5
A16: K2. Простота реализации | B16: =IF(Оценки_Критерии!$I$3>=Оценки_Критерии!$I$2,MIN(9,1+Оценки_Критерии!$I$3-Оценки_Критерии!$I$2),1/MIN(9,1+Оценки_Критерии!$I$2-Оценки_Критерии!$I$3)) -> 0.5 | C16: =IF(Оценки_Критерии!$I$3>=Оценки_Критерии!$I$3,MIN(9,1+Оценки_Критерии!$I$3-Оценки_Критерии!$I$3),1/MIN(9,1+Оценки_Критерии!$I$3-Оценки_Критерии!$I$3)) -> 1 | D16: =IF(Оценки_Критерии!$I$3>=Оценки_Критерии!$I$4,MIN(9,1+Оценки_Критерии!$I$3-Оценки_Критерии!$I$4),1/MIN(9,1+Оценки_Критерии!$I$4-Оценки_Критерии!$I$3)) -> 2 | E16: =IF(Оценки_Критерии!$I$3>=Оценки_Критерии!$I$5,MIN(9,1+Оценки_Критерии!$I$3-Оценки_Критерии!$I$5),1/MIN(9,1+Оценки_Критерии!$I$5-Оценки_Критерии!$I$3)) -> 0.33333333
A17: K3. Низкий риск | B17: =IF(Оценки_Критерии!$I$4>=Оценки_Критерии!$I$2,MIN(9,1+Оценки_Критерии!$I$4-Оценки_Критерии!$I$2),1/MIN(9,1+Оценки_Критерии!$I$2-Оценки_Критерии!$I$4)) -> 0.33333333 | C17: =IF(Оценки_Критерии!$I$4>=Оценки_Критерии!$I$3,MIN(9,1+Оценки_Критерии!$I$4-Оценки_Критерии!$I$3),1/MIN(9,1+Оценки_Критерии!$I$3-Оценки_Критерии!$I$4)) -> 0.5 | D17: =IF(Оценки_Критерии!$I$4>=Оценки_Критерии!$I$4,MIN(9,1+Оценки_Критерии!$I$4-Оценки_Критерии!$I$4),1/MIN(9,1+Оценки_Критерии!$I$4-Оценки_Критерии!$I$4)) -> 1 | E17: =IF(Оценки_Критерии!$I$4>=Оценки_Критерии!$I$5,MIN(9,1+Оценки_Критерии!$I$4-Оценки_Критерии!$I$5),1/MIN(9,1+Оценки_Критерии!$I$5-Оценки_Критерии!$I$4)) -> 0.25
A18: K4. Потенциал развития | B18: =IF(Оценки_Критерии!$I$5>=Оценки_Критерии!$I$2,MIN(9,1+Оценки_Критерии!$I$5-Оценки_Критерии!$I$2),1/MIN(9,1+Оценки_Критерии!$I$2-Оценки_Критерии!$I$5)) -> 2 | C18: =IF(Оценки_Критерии!$I$5>=Оценки_Критерии!$I$3,MIN(9,1+Оценки_Критерии!$I$5-Оценки_Критерии!$I$3),1/MIN(9,1+Оценки_Критерии!$I$3-Оценки_Критерии!$I$5)) -> 3 | D18: =IF(Оценки_Критерии!$I$5>=Оценки_Критерии!$I$4,MIN(9,1+Оценки_Критерии!$I$5-Оценки_Критерии!$I$4),1/MIN(9,1+Оценки_Критерии!$I$4-Оценки_Критерии!$I$5)) -> 4 | E18: =IF(Оценки_Критерии!$I$5>=Оценки_Критерии!$I$5,MIN(9,1+Оценки_Критерии!$I$5-Оценки_Критерии!$I$5),1/MIN(9,1+Оценки_Критерии!$I$5-Оценки_Критерии!$I$5)) -> 1
A20: Эксперт 4 | B20: K1 | C20: K2 | D20: K3 | E20: K4
A21: K1. Полезность для вуза | B21: =IF(Оценки_Критерии!$L$2>=Оценки_Критерии!$L$2,MIN(9,1+Оценки_Критерии!$L$2-Оценки_Критерии!$L$2),1/MIN(9,1+Оценки_Критерии!$L$2-Оценки_Критерии!$L$2)) -> 1 | C21: =IF(Оценки_Критерии!$L$2>=Оценки_Критерии!$L$3,MIN(9,1+Оценки_Критерии!$L$2-Оценки_Критерии!$L$3),1/MIN(9,1+Оценки_Критерии!$L$3-Оценки_Критерии!$L$2)) -> 4 | D21: =IF(Оценки_Критерии!$L$2>=Оценки_Критерии!$L$4,MIN(9,1+Оценки_Критерии!$L$2-Оценки_Критерии!$L$4),1/MIN(9,1+Оценки_Критерии!$L$4-Оценки_Критерии!$L$2)) -> 3 | E21: =IF(Оценки_Критерии!$L$2>=Оценки_Критерии!$L$5,MIN(9,1+Оценки_Критерии!$L$2-Оценки_Критерии!$L$5),1/MIN(9,1+Оценки_Критерии!$L$5-Оценки_Критерии!$L$2)) -> 2
A22: K2. Простота реализации | B22: =IF(Оценки_Критерии!$L$3>=Оценки_Критерии!$L$2,MIN(9,1+Оценки_Критерии!$L$3-Оценки_Критерии!$L$2),1/MIN(9,1+Оценки_Критерии!$L$2-Оценки_Критерии!$L$3)) -> 0.25 | C22: =IF(Оценки_Критерии!$L$3>=Оценки_Критерии!$L$3,MIN(9,1+Оценки_Критерии!$L$3-Оценки_Критерии!$L$3),1/MIN(9,1+Оценки_Критерии!$L$3-Оценки_Критерии!$L$3)) -> 1 | D22: =IF(Оценки_Критерии!$L$3>=Оценки_Критерии!$L$4,MIN(9,1+Оценки_Критерии!$L$3-Оценки_Критерии!$L$4),1/MIN(9,1+Оценки_Критерии!$L$4-Оценки_Критерии!$L$3)) -> 0.5 | E22: =IF(Оценки_Критерии!$L$3>=Оценки_Критерии!$L$5,MIN(9,1+Оценки_Критерии!$L$3-Оценки_Критерии!$L$5),1/MIN(9,1+Оценки_Критерии!$L$5-Оценки_Критерии!$L$3)) -> 0.33333333
A23: K3. Низкий риск | B23: =IF(Оценки_Критерии!$L$4>=Оценки_Критерии!$L$2,MIN(9,1+Оценки_Критерии!$L$4-Оценки_Критерии!$L$2),1/MIN(9,1+Оценки_Критерии!$L$2-Оценки_Критерии!$L$4)) -> 0.33333333 | C23: =IF(Оценки_Критерии!$L$4>=Оценки_Критерии!$L$3,MIN(9,1+Оценки_Критерии!$L$4-Оценки_Критерии!$L$3),1/MIN(9,1+Оценки_Критерии!$L$3-Оценки_Критерии!$L$4)) -> 2 | D23: =IF(Оценки_Критерии!$L$4>=Оценки_Критерии!$L$4,MIN(9,1+Оценки_Критерии!$L$4-Оценки_Критерии!$L$4),1/MIN(9,1+Оценки_Критерии!$L$4-Оценки_Критерии!$L$4)) -> 1 | E23: =IF(Оценки_Критерии!$L$4>=Оценки_Критерии!$L$5,MIN(9,1+Оценки_Критерии!$L$4-Оценки_Критерии!$L$5),1/MIN(9,1+Оценки_Критерии!$L$5-Оценки_Критерии!$L$4)) -> 0.5
A24: K4. Потенциал развития | B24: =IF(Оценки_Критерии!$L$5>=Оценки_Критерии!$L$2,MIN(9,1+Оценки_Критерии!$L$5-Оценки_Критерии!$L$2),1/MIN(9,1+Оценки_Критерии!$L$2-Оценки_Критерии!$L$5)) -> 0.5 | C24: =IF(Оценки_Критерии!$L$5>=Оценки_Критерии!$L$3,MIN(9,1+Оценки_Критерии!$L$5-Оценки_Критерии!$L$3),1/MIN(9,1+Оценки_Критерии!$L$3-Оценки_Критерии!$L$5)) -> 3 | D24: =IF(Оценки_Критерии!$L$5>=Оценки_Критерии!$L$4,MIN(9,1+Оценки_Критерии!$L$5-Оценки_Критерии!$L$4),1/MIN(9,1+Оценки_Критерии!$L$4-Оценки_Критерии!$L$5)) -> 2 | E24: =IF(Оценки_Критерии!$L$5>=Оценки_Критерии!$L$5,MIN(9,1+Оценки_Критерии!$L$5-Оценки_Критерии!$L$5),1/MIN(9,1+Оценки_Критерии!$L$5-Оценки_Критерии!$L$5)) -> 1
A26: Коллективная матрица (геом. среднее) | B26: K1 | C26: K2 | D26: K3 | E26: K4 | F26: Среднее геом. строки | G26: Приоритет w
A27: K1. Полезность для вуза | B27: =GEOMEAN(B3,B9,B15,B21) -> 1 | C27: =GEOMEAN(C3,C9,C15,C21) -> 2.9129506 | D27: =GEOMEAN(D3,D9,D15,D21) -> 3 | E27: =GEOMEAN(E3,E9,E15,E21) -> 1 | F27: =GEOMEAN(B27:E27) -> 1.7193472 | G27: =F27/SUM($F$27:$F$30) -> 0.37496181
A28: K2. Простота реализации | B28: =GEOMEAN(B4,B10,B16,B22) -> 0.34329452 | C28: =GEOMEAN(C4,C10,C16,C22) -> 1 | D28: =GEOMEAN(D4,D10,D16,D22) -> 1 | E28: =GEOMEAN(E4,E10,E16,E22) -> 0.34329452 | F28: =GEOMEAN(B28:E28) -> 0.58591341 | G28: =F28/SUM($F$27:$F$30) -> 0.12777823
A29: K3. Низкий риск | B29: =GEOMEAN(B5,B11,B17,B23) -> 0.33333333 | C29: =GEOMEAN(C5,C11,C17,C23) -> 1 | D29: =GEOMEAN(D5,D11,D17,D23) -> 1 | E29: =GEOMEAN(E5,E11,E17,E23) -> 0.35355339 | F29: =GEOMEAN(B29:E29) -> 0.58591341 | G29: =F29/SUM($F$27:$F$30) -> 0.12777823
A30: K4. Потенциал развития | B30: =GEOMEAN(B6,B12,B18,B24) -> 1 | C30: =GEOMEAN(C6,C12,C18,C24) -> 2.9129506 | D30: =GEOMEAN(D6,D12,D18,D24) -> 2.8284271 | E30: =GEOMEAN(E6,E12,E18,E24) -> 1 | F30: =GEOMEAN(B30:E30) -> 1.6942189 | G30: =F30/SUM($F$27:$F$30) -> 0.36948173
A31: λmax | B31: =SUM(B27:B30)*G27+SUM(C27:C30)*G28+SUM(D27:D30)*G29+SUM(E27:E30)*G30 -> 4.0003517
A32: ИС = (λmax−n)/(n−1) | B32: =(B31-4)/(4-1) -> 0.00011721867
A33: ОС = ИС/СИ (СИ=0.9) | B33: =B32/0.9 -> 0.00013024296 | C33: =IF(B33<=0.1,"согласовано (ОС ≤ 0,10)","ОС > 0,10 — пересмотреть") -> согласовано (ОС ≤ 0,10)
A35: 2. Альтернативы по критерию K1. Полезность для вуза
A36: Эксперт 1 | B36: A. | C36: B. | D36: C. | E36: D.
A37: A. Электронный студенческий офис | B37: =IF(Оценки_Альтернативы!$C$3>=Оценки_Альтернативы!$C$3,MIN(9,1+Оценки_Альтернативы!$C$3-Оценки_Альтернативы!$C$3),1/MIN(9,1+Оценки_Альтернативы!$C$3-Оценки_Альтернативы!$C$3)) -> 1 | C37: =IF(Оценки_Альтернативы!$C$3>=Оценки_Альтернативы!$C$4,MIN(9,1+Оценки_Альтернативы!$C$3-Оценки_Альтернативы!$C$4),1/MIN(9,1+Оценки_Альтернативы!$C$4-Оценки_Альтернативы!$C$3)) -> 2 | D37: =IF(Оценки_Альтернативы!$C$3>=Оценки_Альтернативы!$C$5,MIN(9,1+Оценки_Альтернативы!$C$3-Оценки_Альтернативы!$C$5),1/MIN(9,1+Оценки_Альтернативы!$C$5-Оценки_Альтернативы!$C$3)) -> 2 | E37: =IF(Оценки_Альтернативы!$C$3>=Оценки_Альтернативы!$C$6,MIN(9,1+Оценки_Альтернативы!$C$3-Оценки_Альтернативы!$C$6),1/MIN(9,1+Оценки_Альтернативы!$C$6-Оценки_Альтернативы!$C$3)) -> 1
A38: B. Умное расписание + аудитории | B38: =IF(Оценки_Альтернативы!$C$4>=Оценки_Альтернативы!$C$3,MIN(9,1+Оценки_Альтернативы!$C$4-Оценки_Альтернативы!$C$3),1/MIN(9,1+Оценки_Альтернативы!$C$3-Оценки_Альтернативы!$C$4)) -> 0.5 | C38: =IF(Оценки_Альтернативы!$C$4>=Оценки_Альтернативы!$C$4,MIN(9,1+Оценки_Альтернативы!$C$4-Оценки_Альтернативы!$C$4),1/MIN(9,1+Оценки_Альтернативы!$C$4-Оценки_Альтернативы!$C$4)) -> 1 | D38: =IF(Оценки_Альтернативы!$C$4>=Оценки_Альтернативы!$C$5,MIN(9,1+Оценки_Альтернативы!$C$4-Оценки_Альтернативы!$C$5),1/MIN(9,1+Оценки_Альтернативы!$C$5-Оценки_Альтернативы!$C$4)) -> 1 | E38: =IF(Оценки_Альтернативы!$C$4>=Оценки_Альтернативы!$C$6,MIN(9,1+Оценки_Альтернативы!$C$4-Оценки_Альтернативы!$C$6),1/MIN(9,1+Оценки_Альтернативы!$C$6-Оценки_Альтернативы!$C$4)) -> 0.5
A39: C. Портал научных проектов магистрантов | B39: =IF(Оценки_Альтернативы!$C$5>=Оценки_Альтернативы!$C$3,MIN(9,1+Оценки_Альтернативы!$C$5-Оценки_Альтернативы!$C$3),1/MIN(9,1+Оценки_Альтернативы!$C$3-Оценки_Альтернативы!$C$5)) -> 0.5 | C39: =IF(Оценки_Альтернативы!$C$5>=Оценки_Альтернативы!$C$4,MIN(9,1+Оценки_Альтернативы!$C$5-Оценки_Альтернативы!$C$4),1/MIN(9,1+Оценки_Альтернативы!$C$4-Оценки_Альтернативы!$C$5)) -> 1 | D39: =IF(Оценки_Альтернативы!$C$5>=Оценки_Альтернативы!$C$5,MIN(9,1+Оценки_Альтернативы!$C$5-Оценки_Альтернативы!$C$5),1/MIN(9,1+Оценки_Альтернативы!$C$5-Оценки_Альтернативы!$C$5)) -> 1 | E39: =IF(Оценки_Альтернативы!$C$5>=Оценки_Альтернативы!$C$6,MIN(9,1+Оценки_Альтернативы!$C$5-Оценки_Альтернативы!$C$6),1/MIN(9,1+Оценки_Альтернативы!$C$6-Оценки_Альтернативы!$C$5)) -> 0.5
A40: D. Личный кабинет абитуриента | B40: =IF(Оценки_Альтернативы!$C$6>=Оценки_Альтернативы!$C$3,MIN(9,1+Оценки_Альтернативы!$C$6-Оценки_Альтернативы!$C$3),1/MIN(9,1+Оценки_Альтернативы!$C$3-Оценки_Альтернативы!$C$6)) -> 1 | C40: =IF(Оценки_Альтернативы!$C$6>=Оценки_Альтернативы!$C$4,MIN(9,1+Оценки_Альтернативы!$C$6-Оценки_Альтернативы!$C$4),1/MIN(9,1+Оценки_Альтернативы!$C$4-Оценки_Альтернативы!$C$6)) -> 2 | D40: =IF(Оценки_Альтернативы!$C$6>=Оценки_Альтернативы!$C$5,MIN(9,1+Оценки_Альтернативы!$C$6-Оценки_Альтернативы!$C$5),1/MIN(9,1+Оценки_Альтернативы!$C$5-Оценки_Альтернативы!$C$6)) -> 2 | E40: =IF(Оценки_Альтернативы!$C$6>=Оценки_Альтернативы!$C$6,MIN(9,1+Оценки_Альтернативы!$C$6-Оценки_Альтернативы!$C$6),1/MIN(9,1+Оценки_Альтернативы!$C$6-Оценки_Альтернативы!$C$6)) -> 1
A42: Эксперт 2 | B42: A. | C42: B. | D42: C. | E42: D.
A43: A. Электронный студенческий офис | B43: =IF(Оценки_Альтернативы!$C$10>=Оценки_Альтернативы!$C$10,MIN(9,1+Оценки_Альтернативы!$C$10-Оценки_Альтернативы!$C$10),1/MIN(9,1+Оценки_Альтернативы!$C$10-Оценки_Альтернативы!$C$10)) -> 1 | C43: =IF(Оценки_Альтернативы!$C$10>=Оценки_Альтернативы!$C$11,MIN(9,1+Оценки_Альтернативы!$C$10-Оценки_Альтернативы!$C$11),1/MIN(9,1+Оценки_Альтернативы!$C$11-Оценки_Альтернативы!$C$10)) -> 2 | D43: =IF(Оценки_Альтернативы!$C$10>=Оценки_Альтернативы!$C$12,MIN(9,1+Оценки_Альтернативы!$C$10-Оценки_Альтернативы!$C$12),1/MIN(9,1+Оценки_Альтернативы!$C$12-Оценки_Альтернативы!$C$10)) -> 2 | E43: =IF(Оценки_Альтернативы!$C$10>=Оценки_Альтернативы!$C$13,MIN(9,1+Оценки_Альтернативы!$C$10-Оценки_Альтернативы!$C$13),1/MIN(9,1+Оценки_Альтернативы!$C$13-Оценки_Альтернативы!$C$10)) -> 0.5
A44: B. Умное расписание + аудитории | B44: =IF(Оценки_Альтернативы!$C$11>=Оценки_Альтернативы!$C$10,MIN(9,1+Оценки_Альтернативы!$C$11-Оценки_Альтернативы!$C$10),1/MIN(9,1+Оценки_Альтернативы!$C$10-Оценки_Альтернативы!$C$11)) -> 0.5 | C44: =IF(Оценки_Альтернативы!$C$11>=Оценки_Альтернативы!$C$11,MIN(9,1+Оценки_Альтернативы!$C$11-Оценки_Альтернативы!$C$11),1/MIN(9,1+Оценки_Альтернативы!$C$11-Оценки_Альтернативы!$C$11)) -> 1 | D44: =IF(Оценки_Альтернативы!$C$11>=Оценки_Альтернативы!$C$12,MIN(9,1+Оценки_Альтернативы!$C$11-Оценки_Альтернативы!$C$12),1/MIN(9,1+Оценки_Альтернативы!$C$12-Оценки_Альтернативы!$C$11)) -> 1 | E44: =IF(Оценки_Альтернативы!$C$11>=Оценки_Альтернативы!$C$13,MIN(9,1+Оценки_Альтернативы!$C$11-Оценки_Альтернативы!$C$13),1/MIN(9,1+Оценки_Альтернативы!$C$13-Оценки_Альтернативы!$C$11)) -> 0.33333333
A45: C. Портал научных проектов магистрантов | B45: =IF(Оценки_Альтернативы!$C$12>=Оценки_Альтернативы!$C$10,MIN(9,1+Оценки_Альтернативы!$C$12-Оценки_Альтернативы!$C$10),1/MIN(9,1+Оценки_Альтернативы!$C$10-Оценки_Альтернативы!$C$12)) -> 0.5 | C45: =IF(Оценки_Альтернативы!$C$12>=Оценки_Альтернативы!$C$11,MIN(9,1+Оценки_Альтернативы!$C$12-Оценки_Альтернативы!$C$11),1/MIN(9,1+Оценки_Альтернативы!$C$11-Оценки_Альтернативы!$C$12)) -> 1 | D45: =IF(Оценки_Альтернативы!$C$12>=Оценки_Альтернативы!$C$12,MIN(9,1+Оценки_Альтернативы!$C$12-Оценки_Альтернативы!$C$12),1/MIN(9,1+Оценки_Альтернативы!$C$12-Оценки_Альтернативы!$C$12)) -> 1 | E45: =IF(Оценки_Альтернативы!$C$12>=Оценки_Альтернативы!$C$13,MIN(9,1+Оценки_Альтернативы!$C$12-Оценки_Альтернативы!$C$13),1/MIN(9,1+Оценки_Альтернативы!$C$13-Оценки_Альтернативы!$C$12)) -> 0.33333333
A46: D. Личный кабинет абитуриента | B46: =IF(Оценки_Альтернативы!$C$13>=Оценки_Альтернативы!$C$10,MIN(9,1+Оценки_Альтернативы!$C$13-Оценки_Альтернативы!$C$10),1/MIN(9,1+Оценки_Альтернативы!$C$10-Оценки_Альтернативы!$C$13)) -> 2 | C46: =IF(Оценки_Альтернативы!$C$13>=Оценки_Альтернативы!$C$11,MIN(9,1+Оценки_Альтернативы!$C$13-Оценки_Альтернативы!$C$11),1/MIN(9,1+Оценки_Альтернативы!$C$11-Оценки_Альтернативы!$C$13)) -> 3 | D46: =IF(Оценки_Альтернативы!$C$13>=Оценки_Альтернативы!$C$12,MIN(9,1+Оценки_Альтернативы!$C$13-Оценки_Альтернативы!$C$12),1/MIN(9,1+Оценки_Альтернативы!$C$12-Оценки_Альтернативы!$C$13)) -> 3 | E46: =IF(Оценки_Альтернативы!$C$13>=Оценки_Альтернативы!$C$13,MIN(9,1+Оценки_Альтернативы!$C$13-Оценки_Альтернативы!$C$13),1/MIN(9,1+Оценки_Альтернативы!$C$13-Оценки_Альтернативы!$C$13)) -> 1
...

Sheet Итоги
A1: Альтернатива | B1: TOPSIS: d⁺ | C1: TOPSIS: d⁻ | D1: TOPSIS: CC | E1: TOPSIS: ранг | F1: МАИ: приоритет | G1: МАИ: ранг | H1: Совпадение рангов
A2: A. Электронный студенческий офис | B2: =TOPSIS!F30 -> 0.74806811 | C2: =TOPSIS!K30 -> 1.4468394 | D2: =TOPSIS!L30 -> 0.65918013 | E2: =TOPSIS!M30 -> 2 | F2: =МАИ!F174 -> 0.25276598 | G2: =МАИ!G174 -> 2 | H2: =IF(E2=G2,"да","нет") -> да
A3: B. Умное расписание + аудитории | B3: =TOPSIS!F31 -> 0.67937064 | C3: =TOPSIS!K31 -> 1.5062757 | D3: =TOPSIS!L31 -> 0.68916717 | E3: =TOPSIS!M31 -> 1 | F3: =МАИ!F175 -> 0.22992668 | G3: =МАИ!G175 -> 4 | H3: =IF(E3=G3,"да","нет") -> нет
A4: C. Портал научных проектов магистрантов | B4: =TOPSIS!F32 -> 0.93883875 | C4: =TOPSIS!K32 -> 1.2145616 | D4: =TOPSIS!L32 -> 0.56402035 | E4: =TOPSIS!M32 -> 4 | F4: =МАИ!F176 -> 0.23522225 | G4: =МАИ!G176 -> 3 | H4: =IF(E4=G4,"да","нет") -> нет
A5: D. Личный кабинет абитуриента | B5: =TOPSIS!F33 -> 0.72951652 | C5: =TOPSIS!K33 -> 1.4070748 | D5: =TOPSIS!L33 -> 0.65856058 | E5: =TOPSIS!M33 -> 3 | F5: =МАИ!F177 -> 0.2820851 | G5: =МАИ!G177 -> 1 | H5: =IF(E5=G5,"да","нет") -> нет
A7: Рекомендуемая альтернатива по TOPSIS | B7: =INDEX(A2:A5,MATCH(1,E2:E5,0)) -> B. Умное расписание + аудитории
A8: Рекомендуемая альтернатива по МАИ | B8: =INDEX(A2:A5,MATCH(1,G2:G5,0)) -> D. Личный кабинет абитуриента
